<?xml version='1.0' encoding='utf-8'?>
<robot name="g1_29dof">
  <material name="dark">
    <color rgba="0.2 0.2 0.2 1" />
  </material>
  <material name="white">
    <color rgba="0.7 0.7 0.7 1" />
  </material>

  <material name="Black">
    <color rgba="0.0 0.0 0.0 1.0"/>
  </material>
  <material name="Blue">
    <color rgba="0.0 0.0 0.8 1.0"/>
  </material>
  <material name="Green">
    <color rgba="0.0 0.8 0.0 1.0"/>
  </material>
  <material name="Grey">
    <color rgba="0.4 0.4 0.4 1.0"/>
  </material>
  <material name="Orange">
    <color rgba="1.0 0.4235 0.0392 1.0"/>
  </material>
  <material name="Brown">
    <color rgba="0.8706 0.8118 0.7647 1.0"/>
  </material>
  <material name="Red">
    <color rgba="0.8 0.0 0.0 1.0"/>
  </material>
  <material name="White">
    <color rgba="1.0 1.0 1.0 1.0"/>
  </material>

  <mujoco>
    <compiler meshdir="meshes" discardvisual="false" />
  </mujoco>

  <link name="pelvis">
    <inertial>
      <origin xyz="0 0 -0.07605" rpy="0 0 0" />
      <mass value="3.813" />
      <inertia ixx="0.010549" ixy="0" ixz="2.1E-06" iyy="0.0093089" iyz="0" izz="0.0079184" />
    </inertial>
    <visual>
      <origin xyz="0 0 0" rpy="0 0 0" />
      <geometry>
        <mesh filename="meshes/pelvis.STL" />
      </geometry>
      <material name="dark" />
    </visual>
  </link>
  <link name="pelvis_contour_link">
    <inertial>
      <origin xyz="0 0 0" rpy="0 0 0" />
      <mass value="0.001" />
      <inertia ixx="1e-7" ixy="0" ixz="0" iyy="1e-7" iyz="0" izz="1e-7" />
    </inertial>
    <visual>
      <origin xyz="0 0 0" rpy="0 0 0" />
      <geometry>
        <mesh filename="meshes/pelvis_contour_link.STL" />
      </geometry>
      <material name="white" />
    </visual>
    <collision>
      <origin xyz="0 0 0" rpy="0 0 0" />
      <geometry>
        <mesh filename="meshes/pelvis_contour_link.STL" />
      </geometry>
    </collision>
  </link>
  <joint name="pelvis_contour_joint" type="fixed">
    <parent link="pelvis" />
    <child link="pelvis_contour_link" />
  </joint>

  
  <link name="left_hip_pitch_link">
    <inertial>
      <origin xyz="0.002741 0.047791 -0.02606" rpy="0 0 0" />
      <mass value="1.35" />
      <inertia ixx="0.001811" ixy="3.68E-05" ixz="-3.44E-05" iyy="0.0014193" iyz="0.000171" izz="0.0012812" />
    </inertial>
    <visual>
      <origin xyz="0 0 0" rpy="0 0 0" />
      <geometry>
        <mesh filename="meshes/left_hip_pitch_link.STL" />
      </geometry>
      <material name="dark" />
    </visual>
    <collision>
      <origin xyz="0 0 0" rpy="0 0 0" />
      <geometry>
        <mesh filename="meshes/left_hip_pitch_link.STL" />
      </geometry>
    </collision>
  </link>
  <joint name="left_hip_pitch_joint" type="fixed">
    <origin xyz="0 0.064452 -0.1027" rpy="0 0 0" />
    <parent link="pelvis" />
    <child link="left_hip_pitch_link" />
    </joint>
  <link name="left_hip_roll_link">
    <inertial>
      <origin xyz="0.029812 -0.001045 -0.087934" rpy="0 0 0" />
      <mass value="1.52" />
      <inertia ixx="0.0023773" ixy="-3.8E-06" ixz="-0.0003908" iyy="0.0024123" iyz="1.84E-05" izz="0.0016595" />
    </inertial>
    <visual>
      <origin xyz="0 0 0" rpy="0 0 0" />
      <geometry>
        <mesh filename="meshes/left_hip_roll_link.STL" />
      </geometry>
      <material name="white" />
    </visual>
    <collision>
      <origin xyz="0 0 0" rpy="0 0 0" />
      <geometry>
        <mesh filename="meshes/left_hip_roll_link.STL" />
      </geometry>
    </collision>
  </link>
  <joint name="left_hip_roll_joint" type="fixed">
    <origin xyz="0 0.052 -0.030465" rpy="0 -0.1749 0" />
    <parent link="left_hip_pitch_link" />
    <child link="left_hip_roll_link" />
    </joint>
  <link name="left_hip_yaw_link">
    <inertial>
      <origin xyz="-0.057709 -0.010981 -0.15078" rpy="0 0 0" />
      <mass value="1.702" />
      <inertia ixx="0.0057774" ixy="-0.0005411" ixz="-0.0023948" iyy="0.0076124" iyz="-0.0007072" izz="0.003149" />
    </inertial>
    <visual>
      <origin xyz="0 0 0" rpy="0 0 0" />
      <geometry>
        <mesh filename="meshes/left_hip_yaw_link.STL" />
      </geometry>
      <material name="white" />
    </visual>
    <collision>
      <origin xyz="0 0 0" rpy="0 0 0" />
      <geometry>
        <mesh filename="meshes/left_hip_yaw_link.STL" />
      </geometry>
    </collision>
  </link>
  <joint name="left_hip_yaw_joint" type="fixed">
    <origin xyz="0.025001 0 -0.12412" rpy="0 0 0" />
    <parent link="left_hip_roll_link" />
    <child link="left_hip_yaw_link" />
    </joint>
  <link name="left_knee_link">
    <inertial>
      <origin xyz="0.005457 0.003964 -0.12074" rpy="0 0 0" />
      <mass value="1.932" />
      <inertia ixx="0.011329" ixy="4.82E-05" ixz="-4.49E-05" iyy="0.011277" iyz="-0.0007146" izz="0.0015168" />
    </inertial>
    <visual>
      <origin xyz="0 0 0" rpy="0 0 0" />
      <geometry>
        <mesh filename="meshes/left_knee_link.STL" />
      </geometry>
      <material name="white" />
    </visual>
    <collision>
      <origin xyz="0 0 0" rpy="0 0 0" />
      <geometry>
        <mesh filename="meshes/left_knee_link.STL" />
      </geometry>
    </collision>
  </link>
  <joint name="left_knee_joint" type="fixed">
    <origin xyz="-0.078273 0.0021489 -0.17734" rpy="0 0.1749 0" />
    <parent link="left_hip_yaw_link" />
    <child link="left_knee_link" />
    </joint>
  <link name="left_ankle_pitch_link">
    <inertial>
      <origin xyz="-0.007269 0 0.011137" rpy="0 0 0" />
      <mass value="0.074" />
      <inertia ixx="8.4E-06" ixy="0" ixz="-2.9E-06" iyy="1.89E-05" iyz="0" izz="1.26E-05" />
    </inertial>
    <visual>
      <origin xyz="0 0 0" rpy="0 0 0" />
      <geometry>
        <mesh filename="meshes/left_ankle_pitch_link.STL" />
      </geometry>
      <material name="white" />
    </visual>
    <collision>
      <origin xyz="0 0 0" rpy="0 0 0" />
      <geometry>
        <mesh filename="meshes/left_ankle_pitch_link.STL" />
      </geometry>
    </collision>
  </link>
  <joint name="left_ankle_pitch_joint" type="fixed">
    <origin xyz="0 -9.4445E-05 -0.30001" rpy="0 0 0" />
    <parent link="left_knee_link" />
    <child link="left_ankle_pitch_link" />
    </joint>
  <link name="left_ankle_roll_link">
    <inertial>
      <origin xyz="0.026505 0 -0.016425" rpy="0 0 0" />
      <mass value="0.608" />
      <inertia ixx="0.0002231" ixy="2E-07" ixz="8.91E-05" iyy="0.0016161" iyz="-1E-07" izz="0.0016667" />
    </inertial>
    <visual>
      <origin xyz="0 0 0" rpy="0 0 0" />
      <geometry>
        <mesh filename="meshes/left_ankle_roll_link.STL" />
      </geometry>
      <material name="dark" />
    </visual>
    <collision>
      <origin xyz="-0.05 0.025 -0.03" rpy="0 0 0" />
      <geometry>
        <sphere radius="0.005" />
      </geometry>
    </collision>
    <collision>
      <origin xyz="-0.05 -0.025 -0.03" rpy="0 0 0" />
      <geometry>
        <sphere radius="0.005" />
      </geometry>
    </collision>
    <collision>
      <origin xyz="0.12 0.03 -0.03" rpy="0 0 0" />
      <geometry>
        <sphere radius="0.005" />
      </geometry>
    </collision>
    <collision>
      <origin xyz="0.12 -0.03 -0.03" rpy="0 0 0" />
      <geometry>
        <sphere radius="0.005" />
      </geometry>
    </collision>
  </link>
  <joint name="left_ankle_roll_joint" type="fixed">
    <origin xyz="0 0 -0.017558" rpy="0 0 0" />
    <parent link="left_ankle_pitch_link" />
    <child link="left_ankle_roll_link" />
    </joint>
  <link name="right_hip_pitch_link">
    <inertial>
      <origin xyz="0.002741 -0.047791 -0.02606" rpy="0 0 0" />
      <mass value="1.35" />
      <inertia ixx="0.001811" ixy="-3.68E-05" ixz="-3.44E-05" iyy="0.0014193" iyz="-0.000171" izz="0.0012812" />
    </inertial>
    <visual>
      <origin xyz="0 0 0" rpy="0 0 0" />
      <geometry>
        <mesh filename="meshes/right_hip_pitch_link.STL" />
      </geometry>
      <material name="dark" />
    </visual>
    <collision>
      <origin xyz="0 0 0" rpy="0 0 0" />
      <geometry>
        <mesh filename="meshes/right_hip_pitch_link.STL" />
      </geometry>
    </collision>
  </link>
  <joint name="right_hip_pitch_joint" type="fixed">
    <origin xyz="0 -0.064452 -0.1027" rpy="0 0 0" />
    <parent link="pelvis" />
    <child link="right_hip_pitch_link" />
    </joint>
  <link name="right_hip_roll_link">
    <inertial>
      <origin xyz="0.029812 0.001045 -0.087934" rpy="0 0 0" />
      <mass value="1.52" />
      <inertia ixx="0.0023773" ixy="3.8E-06" ixz="-0.0003908" iyy="0.0024123" iyz="-1.84E-05" izz="0.0016595" />
    </inertial>
    <visual>
      <origin xyz="0 0 0" rpy="0 0 0" />
      <geometry>
        <mesh filename="meshes/right_hip_roll_link.STL" />
      </geometry>
      <material name="white" />
    </visual>
    <collision>
      <origin xyz="0 0 0" rpy="0 0 0" />
      <geometry>
        <mesh filename="meshes/right_hip_roll_link.STL" />
      </geometry>
    </collision>
  </link>
  <joint name="right_hip_roll_joint" type="fixed">
    <origin xyz="0 -0.052 -0.030465" rpy="0 -0.1749 0" />
    <parent link="right_hip_pitch_link" />
    <child link="right_hip_roll_link" />
    </joint>
  <link name="right_hip_yaw_link">
    <inertial>
      <origin xyz="-0.057709 0.010981 -0.15078" rpy="0 0 0" />
      <mass value="1.702" />
      <inertia ixx="0.0057774" ixy="0.0005411" ixz="-0.0023948" iyy="0.0076124" iyz="0.0007072" izz="0.003149" />
    </inertial>
    <visual>
      <origin xyz="0 0 0" rpy="0 0 0" />
      <geometry>
        <mesh filename="meshes/right_hip_yaw_link.STL" />
      </geometry>
      <material name="white" />
    </visual>
    <collision>
      <origin xyz="0 0 0" rpy="0 0 0" />
      <geometry>
        <mesh filename="meshes/right_hip_yaw_link.STL" />
      </geometry>
    </collision>
  </link>
  <joint name="right_hip_yaw_joint" type="fixed">
    <origin xyz="0.025001 0 -0.12412" rpy="0 0 0" />
    <parent link="right_hip_roll_link" />
    <child link="right_hip_yaw_link" />
    </joint>
  <link name="right_knee_link">
    <inertial>
      <origin xyz="0.005457 -0.003964 -0.12074" rpy="0 0 0" />
      <mass value="1.932" />
      <inertia ixx="0.011329" ixy="-4.82E-05" ixz="4.49E-05" iyy="0.011277" iyz="0.0007146" izz="0.0015168" />
    </inertial>
    <visual>
      <origin xyz="0 0 0" rpy="0 0 0" />
      <geometry>
        <mesh filename="meshes/right_knee_link.STL" />
      </geometry>
      <material name="white" />
    </visual>
    <collision>
      <origin xyz="0 0 0" rpy="0 0 0" />
      <geometry>
        <mesh filename="meshes/right_knee_link.STL" />
      </geometry>
    </collision>
  </link>
  <joint name="right_knee_joint" type="fixed">
    <origin xyz="-0.078273 -0.0021489 -0.17734" rpy="0 0.1749 0" />
    <parent link="right_hip_yaw_link" />
    <child link="right_knee_link" />
    </joint>
  <link name="right_ankle_pitch_link">
    <inertial>
      <origin xyz="-0.007269 0 0.011137" rpy="0 0 0" />
      <mass value="0.074" />
      <inertia ixx="8.4E-06" ixy="0" ixz="-2.9E-06" iyy="1.89E-05" iyz="0" izz="1.26E-05" />
    </inertial>
    <visual>
      <origin xyz="0 0 0" rpy="0 0 0" />
      <geometry>
        <mesh filename="meshes/right_ankle_pitch_link.STL" />
      </geometry>
      <material name="white" />
    </visual>
    <collision>
      <origin xyz="0 0 0" rpy="0 0 0" />
      <geometry>
        <mesh filename="meshes/right_ankle_pitch_link.STL" />
      </geometry>
    </collision>
  </link>
  <joint name="right_ankle_pitch_joint" type="fixed">
    <origin xyz="0 9.4445E-05 -0.30001" rpy="0 0 0" />
    <parent link="right_knee_link" />
    <child link="right_ankle_pitch_link" />
    </joint>
  <link name="right_ankle_roll_link">
    <inertial>
      <origin xyz="0.026505 0 -0.016425" rpy="0 0 0" />
      <mass value="0.608" />
      <inertia ixx="0.0002231" ixy="-2E-07" ixz="8.91E-05" iyy="0.0016161" iyz="1E-07" izz="0.0016667" />
    </inertial>
    <visual>
      <origin xyz="0 0 0" rpy="0 0 0" />
      <geometry>
        <mesh filename="meshes/right_ankle_roll_link.STL" />
      </geometry>
      <material name="dark" />
    </visual>
    <collision>
      <origin xyz="-0.05 0.025 -0.03" rpy="0 0 0" />
      <geometry>
        <sphere radius="0.005" />
      </geometry>
    </collision>
    <collision>
      <origin xyz="-0.05 -0.025 -0.03" rpy="0 0 0" />
      <geometry>
        <sphere radius="0.005" />
      </geometry>
    </collision>
    <collision>
      <origin xyz="0.12 0.03 -0.03" rpy="0 0 0" />
      <geometry>
        <sphere radius="0.005" />
      </geometry>
    </collision>
    <collision>
      <origin xyz="0.12 -0.03 -0.03" rpy="0 0 0" />
      <geometry>
        <sphere radius="0.005" />
      </geometry>
    </collision>
  </link>
  <joint name="right_ankle_roll_joint" type="fixed">
    <origin xyz="0 0 -0.017558" rpy="0 0 0" />
    <parent link="right_ankle_pitch_link" />
    <child link="right_ankle_roll_link" />
    </joint>

  
  <link name="waist_yaw_link">
    <inertial>
      <origin xyz="0.003964 0 0.018769" rpy="0 0 0" />
      <mass value="0.244" />
      <inertia ixx="9.9587E-05" ixy="-1.833E-06" ixz="-1.2617E-05" iyy="0.00012411" iyz="-1.18E-07" izz="0.00015586" />
    </inertial>
    <visual>
      <origin xyz="0 0 0" rpy="0 0 0" />
      <geometry>
        <mesh filename="meshes/waist_yaw_link.STL" />
      </geometry>
      <material name="white" />
    </visual>
  </link>
  <joint name="waist_yaw_joint" type="fixed">
    <origin xyz="0 0 0" rpy="0 0 0" />
    <parent link="pelvis" />
    <child link="waist_yaw_link" />
    </joint>
  <link name="waist_roll_link">
    <inertial>
      <origin xyz="0 -0.000236 0.010111" rpy="0 0 0" />
      <mass value="0.047" />
      <inertia ixx="7.515E-06" ixy="0" ixz="0" iyy="6.398E-06" iyz="9.9E-08" izz="3.988E-06" />
    </inertial>
    <visual>
      <origin xyz="0 0 0" rpy="0 0 0" />
      <geometry>
        <mesh filename="meshes/waist_roll_link.STL" />
      </geometry>
      <material name="white" />
    </visual>
  </link>
  <joint name="waist_roll_joint" type="fixed">
    <origin xyz="-0.0039635 0 0.035" rpy="0 0 0" />
    <parent link="waist_yaw_link" />
    <child link="waist_roll_link" />
    </joint>
  <link name="torso_link">
    <inertial>
      <origin xyz="0.002601 0.000257 0.153719" rpy="0 0 0" />
      <mass value="8.562" />
      <inertia ixx="0.065674966" ixy="-8.597E-05" ixz="-0.001737252" iyy="0.053535188" iyz="8.6899E-05" izz="0.030808125" />
    </inertial>
    <visual>
      <origin xyz="0 0 0" rpy="0 0 0" />
      <geometry>
        <mesh filename="meshes/torso_link.STL" />
      </geometry>
      <material name="white" />
    </visual>
    <collision>
      <origin xyz="0 0 0" rpy="0 0 0" />
      <geometry>
        <mesh filename="meshes/torso_link.STL" />
      </geometry>
    </collision>
  </link>
  <joint name="waist_pitch_joint" type="fixed">
    <origin xyz="0 0 0.019" rpy="0 0 0" />
    <parent link="waist_roll_link" />
    <child link="torso_link" />
    </joint>

  
  <joint name="logo_joint" type="fixed">
    <origin xyz="0.0039635 0 -0.054" rpy="0 0 0" />
    <parent link="torso_link" />
    <child link="logo_link" />
  </joint>
  <link name="logo_link">
    <inertial>
      <origin xyz="0 0 0" rpy="0 0 0" />
      <mass value="0.001" />
      <inertia ixx="1e-7" ixy="0" ixz="0" iyy="1e-7" iyz="0" izz="1e-7" />
    </inertial>
    <visual>
      <origin xyz="0 0 0" rpy="0 0 0" />
      <geometry>
        <mesh filename="meshes/logo_link.STL" />
      </geometry>
      <material name="dark" />
    </visual>
    <collision>
      <origin xyz="0 0 0" rpy="0 0 0" />
      <geometry>
        <mesh filename="meshes/logo_link.STL" />
      </geometry>
    </collision>
  </link>

  
  <link name="head_link">
    <inertial>
      <origin xyz="0.005267 0.000299 0.449869" rpy="0 0 0" />
      <mass value="1.036" />
      <inertia ixx="0.004085051" ixy="-2.543E-06" ixz="-6.9455E-05" iyy="0.004185212" iyz="-3.726E-06" izz="0.001807911" />
    </inertial>
    <visual>
      <origin xyz="0 0 0" rpy="0 0 0" />
      <geometry>
        <mesh filename="meshes/head_link.STL" />
      </geometry>
      <material name="dark" />
    </visual>
    <collision>
      <origin xyz="0 0 0" rpy="0 0 0" />
      <geometry>
        <mesh filename="meshes/head_link.STL" />
      </geometry>
    </collision>
  </link>
  <joint name="head_joint" type="fixed">
    <origin xyz="0.0039635 0 -0.054" rpy="0 0 0" />
    <parent link="torso_link" />
    <child link="head_link" />
  </joint>

  
  <link name="waist_support_link">
    <inertial>
      <origin xyz="0 0 0" rpy="0 0 0" />
      <mass value="0.001" />
      <inertia ixx="1e-7" ixy="0" ixz="0" iyy="1e-7" iyz="0" izz="1e-7" />
    </inertial>
    <visual>
      <origin xyz="0 0 0" rpy="0 0 0" />
      <geometry>
        <mesh filename="meshes/waist_support_link.STL" />
      </geometry>
      <material name="white" />
    </visual>
    <collision>
      <origin xyz="0 0 0" rpy="0 0 0" />
      <geometry>
        <mesh filename="meshes/waist_support_link.STL" />
      </geometry>
    </collision>
  </link>
  <joint name="waist_support_joint" type="fixed">
    <origin xyz="0.0039635 0 -0.054" rpy="0 0 0" />
    <parent link="torso_link" />
    <child link="waist_support_link" />
  </joint>

  
  <link name="imu_in_torso" />
  <joint name="imu_in_torso_joint" type="fixed">
    <origin xyz="-0.03959 -0.00224 0.13792" rpy="0 0 0" />
    <parent link="torso_link" />
    <child link="imu_in_torso" />
  </joint>

  <link name="imu_in_pelvis" />
  <joint name="imu_in_pelvis_joint" type="fixed">
    <origin xyz="0.04525 0 -0.08339" rpy="0 0 0" />
    <parent link="pelvis" />
    <child link="imu_in_pelvis" />
  </joint>

  
  <link name="d435_link" />
  <joint name="d435_joint" type="fixed">
    <origin xyz="0.0576235 0.01753 0.41987" rpy="0 0.8307767239493009 0" />
    <parent link="torso_link" />
    <child link="d435_link" />
  </joint>

  
  <link name="mid360_link" />
  <joint name="mid360_joint" type="fixed">
    <origin xyz="0.0002835 0.00003 0.40618" rpy="0 0.04014257279586953 0" />
    <parent link="torso_link" />
    <child link="mid360_link" />
  </joint>

  
  <link name="left_shoulder_pitch_link">
    <inertial>
      <origin xyz="0 0.035892 -0.011628" rpy="0 0 0" />
      <mass value="0.718" />
      <inertia ixx="0.0004291" ixy="-9.2E-06" ixz="6.4E-06" iyy="0.000453" iyz="2.26E-05" izz="0.000423" />
    </inertial>
    <visual>
      <origin xyz="0 0 0" rpy="0 0 0" />
      <geometry>
        <mesh filename="meshes/left_shoulder_pitch_link.STL" />
      </geometry>
      <material name="white" />
    </visual>
    <collision>
      <origin xyz="0 0.04 -0.01" rpy="0 1.5707963267948966 0" />
      <geometry>
        <cylinder radius="0.03" length="0.05" />
      </geometry>
    </collision>
  </link>
  <joint name="left_shoulder_pitch_joint" type="revolute">
    <origin xyz="0.0039563 0.10022 0.23778" rpy="0.27931 5.4949E-05 -0.00019159" />
    <parent link="torso_link" />
    <child link="left_shoulder_pitch_link" />
    <axis xyz="0 1 0" />
    <limit lower="-3.0892" upper="2.6704" effort="25" velocity="37" />
  </joint>
  <link name="left_shoulder_roll_link">
    <inertial>
      <origin xyz="-0.000227 0.00727 -0.063243" rpy="0 0 0" />
      <mass value="0.643" />
      <inertia ixx="0.0006177" ixy="-1E-06" ixz="8.7E-06" iyy="0.0006912" iyz="-5.3E-06" izz="0.0003894" />
    </inertial>
    <visual>
      <origin xyz="0 0 0" rpy="0 0 0" />
      <geometry>
        <mesh filename="meshes/left_shoulder_roll_link.STL" />
      </geometry>
      <material name="white" />
    </visual>
    <collision>
      <origin xyz="-0.004 0.006 -0.053" rpy="0 0 0" />
      <geometry>
        <cylinder radius="0.03" length="0.03" />
      </geometry>
    </collision>
  </link>
  <joint name="left_shoulder_roll_joint" type="revolute">
    <origin xyz="0 0.038 -0.013831" rpy="-0.27925 0 0" />
    <parent link="left_shoulder_pitch_link" />
    <child link="left_shoulder_roll_link" />
    <axis xyz="1 0 0" />
    <limit lower="-1.5882" upper="2.2515" effort="25" velocity="37" />
  </joint>
  <link name="left_shoulder_yaw_link">
    <inertial>
      <origin xyz="0.010773 -0.002949 -0.072009" rpy="0 0 0" />
      <mass value="0.734" />
      <inertia ixx="0.0009988" ixy="7.9E-06" ixz="0.0001412" iyy="0.0010605" iyz="-2.86E-05" izz="0.0004354" />
    </inertial>
    <visual>
      <origin xyz="0 0 0" rpy="0 0 0" />
      <geometry>
        <mesh filename="meshes/left_shoulder_yaw_link.STL" />
      </geometry>
      <material name="white" />
    </visual>
    <collision>
      <origin xyz="0 0 0" rpy="0 0 0" />
      <geometry>
        <mesh filename="meshes/left_shoulder_yaw_link.STL" />
      </geometry>
    </collision>
  </link>
  <joint name="left_shoulder_yaw_joint" type="revolute">
    <origin xyz="0 0.00624 -0.1032" rpy="0 0 0" />
    <parent link="left_shoulder_roll_link" />
    <child link="left_shoulder_yaw_link" />
    <axis xyz="0 0 1" />
    <limit lower="-2.618" upper="2.618" effort="25" velocity="37" />
  </joint>
  <link name="left_elbow_link">
    <inertial>
      <origin xyz="0.064956 0.004454 -0.010062" rpy="0 0 0" />
      <mass value="0.6" />
      <inertia ixx="0.0002891" ixy="6.53E-05" ixz="1.72E-05" iyy="0.0004152" iyz="-5.6E-06" izz="0.0004197" />
    </inertial>
    <visual>
      <origin xyz="0 0 0" rpy="0 0 0" />
      <geometry>
        <mesh filename="meshes/left_elbow_link.STL" />
      </geometry>
      <material name="white" />
    </visual>
    <collision>
      <origin xyz="0 0 0" rpy="0 0 0" />
      <geometry>
        <mesh filename="meshes/left_elbow_link.STL" />
      </geometry>
    </collision>
  </link>
  <joint name="left_elbow_joint" type="revolute">
    <origin xyz="0.015783 0 -0.080518" rpy="0 0 0" />
    <parent link="left_shoulder_yaw_link" />
    <child link="left_elbow_link" />
    <axis xyz="0 1 0" />
    <limit lower="-1.0472" upper="2.0944" effort="25" velocity="37" />
  </joint>
  <joint name="left_wrist_roll_joint" type="revolute">
    <origin xyz="0.100 0.00188791 -0.010" rpy="0 0 0" />
    <axis xyz="1 0 0" />
    <parent link="left_elbow_link" />
    <child link="left_wrist_roll_link" />
    <limit effort="25" velocity="37" lower="-1.972222054" upper="1.972222054" />
  </joint>
  <link name="left_wrist_roll_link">
    <inertial>
      <origin xyz="0.01713944778 0.00053759094 0.00000048864" rpy="0 0 0" />
      <mass value="0.08544498" />
      <inertia ixx="0.00004821544023" ixy="-0.00000424511021" ixz="0.00000000510599" iyy="0.00003722899093" iyz="-0.00000000123525" izz="0.00005482106541" />
    </inertial>
    <visual>
      <origin xyz="0 0 0" rpy="0 0 0" />
      <geometry>
        <mesh filename="meshes/left_wrist_roll_link.STL" />
      </geometry>
      <material name="white" />
    </visual>
    <collision>
      <origin xyz="0 0 0" rpy="0 0 0" />
      <geometry>
        <mesh filename="meshes/left_wrist_roll_link.STL" />
      </geometry>
    </collision>
  </link>
  <joint name="left_wrist_pitch_joint" type="revolute">
    <origin xyz="0.038 0 0" rpy="0 0 0" />
    <axis xyz="0 1 0" />
    <parent link="left_wrist_roll_link" />
    <child link="left_wrist_pitch_link" />
    <limit effort="5" velocity="22" lower="-1.614429558" upper="1.614429558" />
  </joint>
  <link name="left_wrist_pitch_link">
    <inertial>
      <origin xyz="0.02299989837 -0.00111685314 -0.00111658096" rpy="0 0 0" />
      <mass value="0.48404956" />
      <inertia ixx="0.00016579646273" ixy="-0.00001231206746" ixz="0.00001231699194" iyy="0.00042954057410" iyz="0.00000081417712" izz="0.00042953697654" />
    </inertial>
    <visual>
      <origin xyz="0 0 0" rpy="0 0 0" />
      <geometry>
        <mesh filename="meshes/left_wrist_pitch_link.STL" />
      </geometry>
      <material name="white" />
    </visual>
    <collision>
      <origin xyz="0 0 0" rpy="0 0 0" />
      <geometry>
        <mesh filename="meshes/left_wrist_pitch_link.STL" />
      </geometry>
    </collision>
  </link>
  <joint name="left_wrist_yaw_joint" type="revolute">
    <origin xyz="0.046 0 0" rpy="0 0 0" />
    <axis xyz="0 0 1" />
    <parent link="left_wrist_pitch_link" />
    <child link="left_wrist_yaw_link" />
    <limit effort="5" velocity="22" lower="-1.614429558" upper="1.614429558" />
  </joint>
  <link name="left_wrist_yaw_link">
    <inertial>
      <origin xyz="0.02200381568 0.00049485096 0.00053861123" rpy="0 0 0" />
      <mass value="0.08457647" />
      <inertia ixx="0.00004929128828" ixy="-0.00000045735494" ixz="0.00000445867591" iyy="0.00005973338134" iyz="0.00000043217198" izz="0.00003928083826" />
    </inertial>
    <visual>
      <origin xyz="0 0 0" rpy="0 0 0" />
      <geometry>
        <mesh filename="meshes/left_wrist_yaw_link.STL" />
      </geometry>
      <material name="white" />
    </visual>
    <collision>
      <origin xyz="0 0 0" rpy="0 0 0" />
      <geometry>
        <mesh filename="meshes/left_wrist_yaw_link.STL" />
      </geometry>
    </collision>
  </link>
  <link name="right_shoulder_pitch_link">
    <inertial>
      <origin xyz="0 -0.035892 -0.011628" rpy="0 0 0" />
      <mass value="0.718" />
      <inertia ixx="0.0004291" ixy="9.2E-06" ixz="6.4E-06" iyy="0.000453" iyz="-2.26E-05" izz="0.000423" />
    </inertial>
    <visual>
      <origin xyz="0 0 0" rpy="0 0 0" />
      <geometry>
        <mesh filename="meshes/right_shoulder_pitch_link.STL" />
      </geometry>
      <material name="white" />
    </visual>
    <collision>
      <origin xyz="0 -0.04 -0.01" rpy="0 1.5707963267948966 0" />
      <geometry>
        <cylinder radius="0.03" length="0.05" />
      </geometry>
    </collision>
  </link>
  <joint name="right_shoulder_pitch_joint" type="fixed">
    <origin xyz="0.0039563 -0.10021 0.23778" rpy="-0.27931 5.4949E-05 0.00019159" />
    <parent link="torso_link" />
    <child link="right_shoulder_pitch_link" />
    </joint>
  <link name="right_shoulder_roll_link">
    <inertial>
      <origin xyz="-0.000227 -0.00727 -0.063243" rpy="0 0 0" />
      <mass value="0.643" />
      <inertia ixx="0.0006177" ixy="1E-06" ixz="8.7E-06" iyy="0.0006912" iyz="5.3E-06" izz="0.0003894" />
    </inertial>
    <visual>
      <origin xyz="0 0 0" rpy="0 0 0" />
      <geometry>
        <mesh filename="meshes/right_shoulder_roll_link.STL" />
      </geometry>
      <material name="white" />
    </visual>
    <collision>
      <origin xyz="-0.004 -0.006 -0.053" rpy="0 0 0" />
      <geometry>
        <cylinder radius="0.03" length="0.03" />
      </geometry>
    </collision>
  </link>
  <joint name="right_shoulder_roll_joint" type="fixed">
    <origin xyz="0 -0.038 -0.013831" rpy="0.27925 0 0" />
    <parent link="right_shoulder_pitch_link" />
    <child link="right_shoulder_roll_link" />
    </joint>
  <link name="right_shoulder_yaw_link">
    <inertial>
      <origin xyz="0.010773 0.002949 -0.072009" rpy="0 0 0" />
      <mass value="0.734" />
      <inertia ixx="0.0009988" ixy="-7.9E-06" ixz="0.0001412" iyy="0.0010605" iyz="2.86E-05" izz="0.0004354" />
    </inertial>
    <visual>
      <origin xyz="0 0 0" rpy="0 0 0" />
      <geometry>
        <mesh filename="meshes/right_shoulder_yaw_link.STL" />
      </geometry>
      <material name="white" />
    </visual>
    <collision>
      <origin xyz="0 0 0" rpy="0 0 0" />
      <geometry>
        <mesh filename="meshes/right_shoulder_yaw_link.STL" />
      </geometry>
    </collision>
  </link>
  <joint name="right_shoulder_yaw_joint" type="fixed">
    <origin xyz="0 -0.00624 -0.1032" rpy="0 0 0" />
    <parent link="right_shoulder_roll_link" />
    <child link="right_shoulder_yaw_link" />
    </joint>
  <link name="right_elbow_link">
    <inertial>
      <origin xyz="0.064956 -0.004454 -0.010062" rpy="0 0 0" />
      <mass value="0.6" />
      <inertia ixx="0.0002891" ixy="-6.53E-05" ixz="1.72E-05" iyy="0.0004152" iyz="5.6E-06" izz="0.0004197" />
    </inertial>
    <visual>
      <origin xyz="0 0 0" rpy="0 0 0" />
      <geometry>
        <mesh filename="meshes/right_elbow_link.STL" />
      </geometry>
      <material name="white" />
    </visual>
    <collision>
      <origin xyz="0 0 0" rpy="0 0 0" />
      <geometry>
        <mesh filename="meshes/right_elbow_link.STL" />
      </geometry>
    </collision>
  </link>
  <joint name="right_elbow_joint" type="fixed">
    <origin xyz="0.015783 0 -0.080518" rpy="0 0 0" />
    <parent link="right_shoulder_yaw_link" />
    <child link="right_elbow_link" />
    </joint>
  <joint name="right_wrist_roll_joint" type="fixed">
    <origin xyz="0.100 -0.00188791 -0.010" rpy="0 0 0" />
    <parent link="right_elbow_link" />
    <child link="right_wrist_roll_link" />
    </joint>
  <link name="right_wrist_roll_link">
    <inertial>
      <origin xyz="0.01713944778 -0.00053759094 0.00000048864" rpy="0 0 0" />
      <mass value="0.08544498" />
      <inertia ixx="0.00004821544023" ixy="0.00000424511021" ixz="0.00000000510599" iyy="0.00003722899093" iyz="0.00000000123525" izz="0.00005482106541" />
    </inertial>
    <visual>
      <origin xyz="0 0 0" rpy="0 0 0" />
      <geometry>
        <mesh filename="meshes/right_wrist_roll_link.STL" />
      </geometry>
      <material name="white" />
    </visual>
    <collision>
      <origin xyz="0 0 0" rpy="0 0 0" />
      <geometry>
        <mesh filename="meshes/right_wrist_roll_link.STL" />
      </geometry>
    </collision>
  </link>
  <joint name="right_wrist_pitch_joint" type="fixed">
    <origin xyz="0.038 0 0" rpy="0 0 0" />
    <parent link="right_wrist_roll_link" />
    <child link="right_wrist_pitch_link" />
    </joint>
  <link name="right_wrist_pitch_link">
    <inertial>
      <origin xyz="0.02299989837 0.00111685314 -0.00111658096" rpy="0 0 0" />
      <mass value="0.48404956" />
      <inertia ixx="0.00016579646273" ixy="0.00001231206746" ixz="0.00001231699194" iyy="0.00042954057410" iyz="-0.00000081417712" izz="0.00042953697654" />
    </inertial>
    <visual>
      <origin xyz="0 0 0" rpy="0 0 0" />
      <geometry>
        <mesh filename="meshes/right_wrist_pitch_link.STL" />
      </geometry>
      <material name="white" />
    </visual>
    <collision>
      <origin xyz="0 0 0" rpy="0 0 0" />
      <geometry>
        <mesh filename="meshes/right_wrist_pitch_link.STL" />
      </geometry>
    </collision>
  </link>
  <joint name="right_wrist_yaw_joint" type="fixed">
    <origin xyz="0.046 0 0" rpy="0 0 0" />
    <parent link="right_wrist_pitch_link" />
    <child link="right_wrist_yaw_link" />
    </joint>
  <link name="right_wrist_yaw_link">
    <inertial>
      <origin xyz="0.02200381568 -0.00049485096 0.00053861123" rpy="0 0 0" />
      <mass value="0.08457647" />
      <inertia ixx="0.00004929128828" ixy="0.00000045735494" ixz="0.00000445867591" iyy="0.00005973338134" iyz="-0.00000043217198" izz="0.00003928083826" />
    </inertial>
    <visual>
      <origin xyz="0 0 0" rpy="0 0 0" />
      <geometry>
        <mesh filename="meshes/right_wrist_yaw_link.STL" />
      </geometry>
      <material name="white" />
    </visual>
    <collision>
      <origin xyz="0 0 0" rpy="0 0 0" />
      <geometry>
        <mesh filename="meshes/right_wrist_yaw_link.STL" />
      </geometry>
    </collision>
  </link>


  <link name="sharpa_mount">
    <inertial>
      <mass value="0.05"/>
      <origin rpy="0 0 0" xyz="0 0 0"/>
      <inertia ixx="1e-4" ixy="0" ixz="0" iyy="1e-4" iyz="0" izz="1e-4"/>
    </inertial>
  </link>
  <joint name="sharpa_mount_joint" type="fixed">
    <origin rpy="-1.5708 0 -1.5708" xyz="0.0415 0.0 0"/>
    <parent link="sharpa_mount"/>
    <child link="left_hand_C_MC"/>
  </joint>
  <link name="left_hand_C_MC">
    <inertial>
      <origin xyz="-0.00162819 -0.00610534 0.0404193" rpy="0 0 0"/>
      <mass value="0.72045"/>
      <inertia ixx="0.000674245" ixy="-9.22298E-06" ixz="5.25317E-06" iyy="0.000526298" iyz="9.94281E-05" izz="0.000354144"/>
    </inertial>
    <visual>
      <origin xyz="0 0 0" rpy="0 0 0"/>
      <geometry>
        <mesh filename="left_sharpa_meshes/left_hand_C_MC_visual.STL"/>
      </geometry>
      <material name="">
        <color rgba="0.79216 0.81961 0.93333 1"/>
      </material>
    </visual>
    <collision>
      <origin xyz="0 0 0" rpy="0 0 0"/>
      <geometry>
        <mesh filename="left_sharpa_meshes/left_hand_C_MC.STL"/>
      </geometry>
    </collision>
  </link>
  <link name="left_thumb_CMC_VL">
    <inertial>
      <origin xyz="0 0 0" rpy="0 0 0"/>
      <mass value="1.0E-06"/>
      <inertia ixx="2.0E-12" ixy="0" ixz="0" iyy="2.0E-12" iyz="0" izz="2.0E-12"/>
    </inertial>
    <visual>
      <origin xyz="0 0 0" rpy="0 0 0"/>
      <geometry>
        <mesh filename="left_sharpa_meshes/left_thumb_CMC_VL.STL"/>
      </geometry>
      <material name="">
        <color rgba="0.79216 0.81961 0.93333 1"/>
      </material>
    </visual>
  </link>
  <joint name="left_1_thumb_CMC_FE" type="revolute">
    <origin xyz="0.01 -0.026 0.0212" rpy="0 0 -1.5708"/>
    <parent link="left_hand_C_MC"/>
    <child link="left_thumb_CMC_VL"/>
    <axis xyz="0 0 1"/>
    <limit lower="-0.1745" upper="1.9199" effort="3.3" velocity="11.84076833"/>
  </joint>
  <link name="left_thumb_MC">
    <inertial>
      <origin xyz="0.0385056 -0.0105846 -0.00991873" rpy="0 0 0"/>
      <mass value="0.116"/>
      <inertia ixx="1.65891E-05" ixy="-1.79455E-06" ixz="-4.03315E-07" iyy="3.45657E-05" iyz="2.16989E-06" izz="3.70102E-05"/>
    </inertial>
    <visual>
      <origin xyz="0 0 0" rpy="0 0 0"/>
      <geometry>
        <mesh filename="left_sharpa_meshes/left_thumb_MC_visual.STL"/>
      </geometry>
      <material name="">
        <color rgba="0.79216 0.81961 0.93333 1"/>
      </material>
    </visual>
    <collision>
      <origin xyz="0 0 0" rpy="0 0 0"/>
      <geometry>
        <!-- <mesh filename="left_sharpa_meshes/left_thumb_MC_modified.STL" /> -->
        <mesh filename="left_sharpa_meshes/left_thumb_MC.STL"/>
      </geometry>
    </collision>
  </link>
  <joint name="left_thumb_CMC_AA" type="revolute">
    <origin xyz="0 -0.005 0" rpy="1.5708 -0.7854 0"/>
    <parent link="left_thumb_CMC_VL"/>
    <child link="left_thumb_MC"/>
    <axis xyz="0 0 1"/>
    <!-- <limit lower="-0.3491" upper="0.3491" effort="3.3" velocity="11.84076833" /> -->
    <limit lower="-0.3491" upper="0.1309" effort="3.3" velocity="11.84076833"/>
  </joint>
  <link name="left_thumb_MCP_VL">
    <inertial>
      <origin xyz="4.8E-09 0.000869809 -3.6E-09" rpy="0 0 0"/>
      <mass value="1.0E-06"/>
      <inertia ixx="2.0E-12" ixy="0" ixz="0" iyy="2.0E-12" iyz="0" izz="2.0E-12"/>
    </inertial>
    <visual>
      <origin xyz="0 0 0" rpy="0 0 0"/>
      <geometry>
        <mesh filename="left_sharpa_meshes/left_thumb_MCP_VL_visual.STL"/>
      </geometry>
      <material name="">
        <color rgba="0.79216 0.81961 0.93333 1"/>
      </material>
    </visual>
  </link>
  <joint name="left_thumb_MCP_FE" type="revolute">
    <origin xyz="0.065 -0.006 -0.010392" rpy="-0.5236 0 0"/>
    <parent link="left_thumb_MC"/>
    <child link="left_thumb_MCP_VL"/>
    <axis xyz="0 0 1"/>
    <limit lower="-0.5236" upper="1.3963" effort="1.864" velocity="16.07692878"/>
  </joint>
  <link name="left_thumb_PP">
    <inertial>
      <origin xyz="0.0219483 -0.00015581 0.00149446" rpy="0 0 0"/>
      <mass value="0.04955"/>
      <inertia ixx="2.59665E-06" ixy="3.6507E-09" ixz="-1.84385E-07" iyy="4.6E-06" iyz="-3.29002E-10" izz="4.33744E-06"/>
    </inertial>
    <visual>
      <origin xyz="0 0 0" rpy="0 0 0"/>
      <geometry>
        <mesh filename="left_sharpa_meshes/left_thumb_PP_visual.STL"/>
      </geometry>
      <material name="">
        <color rgba="0.79216 0.81961 0.93333 1"/>
      </material>
    </visual>
    <collision>
      <origin xyz="0 0 0" rpy="0 0 0"/>
      <geometry>
        <mesh filename="left_sharpa_meshes/left_thumb_PP.STL"/>
      </geometry>
    </collision>
  </link>
  <joint name="left_thumb_MCP_AA" type="revolute">
    <origin xyz="0 0 0" rpy="1.5708 0 0"/>
    <parent link="left_thumb_MCP_VL"/>
    <child link="left_thumb_PP"/>
    <axis xyz="0 0 1"/>
    <limit lower="-0.3491" upper="0.3491" effort="1.864" velocity="16.07692878"/>
  </joint>
  <link name="left_thumb_DP">
    <inertial>
      <origin xyz="0.0151804 -0.00463639 8.34861E-07" rpy="0 0 0"/>
      <mass value="0.003886"/>
      <inertia ixx="1.32801E-07" ixy="4.59297E-08" ixz="-3.77372E-13" iyy="1.5797E-07" iyz="3.48732E-13" izz="1.50341E-07"/>
    </inertial>
    <visual>
      <origin xyz="0 0 0" rpy="0 0 0"/>
      <geometry>
        <mesh filename="left_sharpa_meshes/left_thumb_DP_visual.STL"/>
      </geometry>
      <material name="">
        <color rgba="0.79216 0.81961 0.93333 1"/>
      </material>
    </visual>
    <collision>
      <origin xyz="0 0 0" rpy="0 0 0"/>
      <geometry>
        <mesh filename="left_sharpa_meshes/left_thumb_DP.STL"/>
      </geometry>
    </collision>
  </link>
  <joint name="left_thumb_IP" type="revolute">
    <origin xyz="0.039 0 0" rpy="-1.5708 0 0"/>
    <parent link="left_thumb_PP"/>
    <child link="left_thumb_DP"/>
    <axis xyz="0 0 1"/>
    <limit lower="0" upper="1.7453" effort="0.638" velocity="11.61831603"/>
  </joint>
  <link name="left_thumb_elastomer">
    <inertial>
      <origin xyz="1.37353E-07 -0.0202873 0.00127072" rpy="0 0 0"/>
      <mass value="0.002100"/>
      <inertia ixx="6.4357E-08" ixy="-6.5027E-12" ixz="5.04872E-12" iyy="5.72112E-08" iyz="1.72427E-08" izz="7.47205E-08"/>
    </inertial>
    <visual>
      <origin xyz="0 0 0" rpy="0 0 0"/>
      <geometry>
        <mesh filename="left_sharpa_meshes/thumb_elastomer_surface.STL"/>
      </geometry>
      <material name="">
        <color rgba="0.2 1 0.2 1"/>
      </material>
    </visual>
    <collision>
      <origin xyz="0 0 0" rpy="0 0 0"/>
      <geometry>
        <mesh filename="left_sharpa_meshes/thumb_elastomer.STL"/>
      </geometry>
    </collision>
  </link>
  <joint name="left_thumb_elastomer_fix_joint" type="fixed">
    <origin xyz="0 0 0" rpy="1.5707963267949 -1.5707963267949 0"/>
    <parent link="left_thumb_DP"/>
    <child link="left_thumb_elastomer"/>
    <axis xyz="0 0 0"/>
  </joint>
  <link name="left_thumb_fingertip">
    <inertial>
      <origin xyz="0.0 0.0 0.0" rpy="0 0 0"/>
      <mass value="1.0E-06"/>
      <inertia ixx="2.0E-12" ixy="0" ixz="0" iyy="2.0E-12" iyz="0" izz="2.0E-12"/>
    </inertial>
  </link>
  <joint name="left_thumb_fingertip_fix_joint" type="fixed">
    <origin xyz="0 -0.0276109346321216 0" rpy="1.5707963267949 1.5707963267949 0"/>
    <parent link="left_thumb_elastomer"/>
    <child link="left_thumb_fingertip"/>
    <axis xyz="0 0 0"/>
  </joint>
  <link name="left_index_MCP_VL">
    <inertial>
      <origin xyz="4.8E-09 0.00086981 -3.6E-09" rpy="0 0 0"/>
      <mass value="1.0E-06"/>
      <inertia ixx="2.0E-12" ixy="0" ixz="0" iyy="2.0E-12" iyz="0" izz="2.0E-12"/>
    </inertial>
    <visual>
      <origin xyz="0 0 0" rpy="0 0 0"/>
      <geometry>
        <mesh filename="left_sharpa_meshes/left_MCP_VL_visual.STL"/>
      </geometry>
      <material name="">
        <color rgba="0.79216 0.81961 0.93333 1"/>
      </material>
    </visual>
    <collision>
      <origin xyz="0 0 0" rpy="0 0 0"/>
      <geometry>
        <mesh filename="left_sharpa_meshes/MCP_VL.STL"/>
      </geometry>
    </collision>
  </link>
  <joint name="left_2_index_MCP_FE" type="revolute">
    <origin xyz="0.001 -0.0303 0.0957" rpy="0 -1.5708 -1.5708"/>
    <parent link="left_hand_C_MC"/>
    <child link="left_index_MCP_VL"/>
    <axis xyz="0 0 1"/>
    <limit lower="-0.17453293" upper="1.5708" effort="1.864" velocity="16.07692878"/>
  </joint>
  <link name="left_index_PP">
    <inertial>
      <origin xyz="0.0243772 -1.00263E-06 0.000755901" rpy="0 0 0"/>
      <mass value="0.04138"/>
      <inertia ixx="2.19643E-06" ixy="-5.66246E-11" ixz="-3.54371E-07" iyy="6.82371E-06" iyz="4.72597E-11" izz="6.51207E-06"/>
    </inertial>
    <visual>
      <origin xyz="0 0 0" rpy="0 0 0"/>
      <geometry>
        <mesh filename="left_sharpa_meshes/left_PP_visual.STL"/>
      </geometry>
      <material name="">
        <color rgba="0.79216 0.81961 0.93333 1"/>
      </material>
    </visual>
    <collision>
      <origin xyz="0 0 0" rpy="0 0 0"/>
      <geometry>
        <mesh filename="left_sharpa_meshes/left_PP.STL"/>
      </geometry>
    </collision>
  </link>
  <joint name="left_index_MCP_AA" type="revolute">
    <origin xyz="0 0 0" rpy="1.5708 0 0"/>
    <parent link="left_index_MCP_VL"/>
    <child link="left_index_PP"/>
    <axis xyz="0 0 1"/>
    <!-- <limit lower="-0.3491" upper="0.3491" effort="1.864" velocity="16.07692878" /> -->
    <limit lower="-0.03491" upper="0.03491" effort="1.864" velocity="16.07692878"/>
  </joint>
  <link name="left_index_MP">
    <inertial>
      <origin xyz="0.015316 -0.00138561 6.27987E-08" rpy="0 0 0"/>
      <mass value="0.02509"/>
      <inertia ixx="1.00375E-06" ixy="-7.00446E-08" ixz="7.42125E-12" iyy="2.2637E-06" iyz="-2.26606E-12" izz="2.28516E-06"/>
    </inertial>
    <visual>
      <origin xyz="0 0 0" rpy="0 0 0"/>
      <geometry>
        <mesh filename="left_sharpa_meshes/left_MP_visual.STL"/>
      </geometry>
      <material name="">
        <color rgba="0.79216 0.81961 0.93333 1"/>
      </material>
    </visual>
    <collision>
      <origin xyz="0 0 0" rpy="0 0 0"/>
      <geometry>
        <mesh filename="left_sharpa_meshes/left_MP.STL"/>
      </geometry>
    </collision>
  </link>
  <joint name="left_index_PIP" type="revolute">
    <origin xyz="0.047 0 0" rpy="-1.5708 0 0"/>
    <parent link="left_index_PP"/>
    <child link="left_index_MP"/>
    <axis xyz="0 0 1"/>
    <limit lower="0" upper="1.7453" effort="0.638" velocity="11.61831603"/>
  </joint>
  <link name="left_index_DP">
    <inertial>
      <origin xyz="0.0127205 -0.00380991 -9.52663E-07" rpy="0 0 0"/>
      <mass value="0.003002"/>
      <inertia ixx="7.65598E-08" ixy="2.47622E-08" ixz="1.23922E-11" iyy="9.99792E-08" iyz="-4.16105E-12" izz="9.38245E-08"/>
    </inertial>
    <visual>
      <origin xyz="0 0 0" rpy="0 0 0"/>
      <geometry>
        <mesh filename="left_sharpa_meshes/left_DP_visual.STL"/>
      </geometry>
      <material name="">
        <color rgba="0.79216 0.81961 0.93333 1"/>
      </material>
    </visual>
    <collision>
      <origin xyz="0 0 0" rpy="0 0 0"/>
      <geometry>
        <mesh filename="left_sharpa_meshes/left_DP.STL"/>
      </geometry>
    </collision>
  </link>
  <joint name="left_index_DIP" type="revolute">
    <origin xyz="0.0315 0 0" rpy="0 0 0"/>
    <parent link="left_index_MP"/>
    <child link="left_index_DP"/>
    <axis xyz="0 0 1"/>
    <limit lower="0" upper="1.3963" effort="0.189369" velocity="14.66594768"/>
  </joint>
  <link name="left_index_elastomer">
    <inertial>
      <origin xyz="-4.34641E-07 -0.0183002 0.000412898" rpy="0 0 0"/>
      <mass value="0.00110"/>
      <inertia ixx="2.54635E-08" ixy="1.30327E-12" ixz="-2.13894E-13" iyy="2.14666E-08" iyz="5.39858E-09" izz="2.96037E-08"/>
    </inertial>
    <visual>
      <origin xyz="0 0 0" rpy="0 0 0"/>
      <geometry>
        <mesh filename="left_sharpa_meshes/elastomer_surface.STL"/>
      </geometry>
      <material name="">
        <color rgba="0.2 1 0.2 1"/>
      </material>
    </visual>
    <collision>
      <origin xyz="0 0 0" rpy="0 0 0"/>
      <geometry>
        <mesh filename="left_sharpa_meshes/elastomer.STL"/>
      </geometry>
    </collision>
  </link>
  <joint name="left_index_elastomer_fix_joint" type="fixed">
    <origin xyz="0 0 0" rpy="1.5707963267949 -1.5707963267949 0"/>
    <parent link="left_index_DP"/>
    <child link="left_index_elastomer"/>
    <axis xyz="0 0 0"/>
  </joint>
  <link name="left_index_fingertip">
    <inertial>
      <origin xyz="0.0 0.0 0.0" rpy="0 0 0"/>
      <mass value="1.0E-06"/>
      <inertia ixx="2.0E-12" ixy="0" ixz="0" iyy="2.0E-12" iyz="0" izz="2.0E-12"/>
    </inertial>
  </link>
  <joint name="left_index_fingertip_fix_joint" type="fixed">
    <origin xyz="0 -0.0260092574262508 0" rpy="1.5707963267949 1.5707963267949 0"/>
    <parent link="left_index_elastomer"/>
    <child link="left_index_fingertip"/>
    <axis xyz="0 0 0"/>
  </joint>
  <link name="left_middle_MCP_VL">
    <inertial>
      <origin xyz="4.8E-09 0.00086981 -3.6E-09" rpy="0 0 0"/>
      <mass value="1.0E-06"/>
      <inertia ixx="2.0E-12" ixy="0" ixz="0" iyy="2.0E-12" iyz="0" izz="2.0E-12"/>
    </inertial>
    <visual>
      <origin xyz="0 0 0" rpy="0 0 0"/>
      <geometry>
        <mesh filename="left_sharpa_meshes/left_MCP_VL_visual.STL"/>
      </geometry>
      <material name="">
        <color rgba="0.79216 0.81961 0.93333 1"/>
      </material>
    </visual>
    <collision>
      <origin xyz="0 0 0" rpy="0 0 0"/>
      <geometry>
        <mesh filename="left_sharpa_meshes/MCP_VL.STL"/>
      </geometry>
    </collision>
  </link>
  <joint name="left_3_middle_MCP_FE" type="revolute">
    <origin xyz="0 -0.01 0.0987" rpy="0 -1.5708 -1.5708"/>
    <parent link="left_hand_C_MC"/>
    <child link="left_middle_MCP_VL"/>
    <axis xyz="0 0 1"/>
    <limit lower="-0.17453293" upper="1.5708" effort="1.864" velocity="16.07692878"/>
  </joint>
  <link name="left_middle_PP">
    <inertial>
      <origin xyz="0.0243772 -1.00263E-06 0.000755901" rpy="0 0 0"/>
      <mass value="0.04138"/>
      <inertia ixx="2.19643E-06" ixy="-5.66246E-11" ixz="-3.54371E-07" iyy="6.82371E-06" iyz="4.72597E-11" izz="6.51207E-06"/>
    </inertial>
    <visual>
      <origin xyz="0 0 0" rpy="0 0 0"/>
      <geometry>
        <mesh filename="left_sharpa_meshes/left_PP_visual.STL"/>
      </geometry>
      <material name="">
        <color rgba="0.79216 0.81961 0.93333 1"/>
      </material>
    </visual>
    <collision>
      <origin xyz="0 0 0" rpy="0 0 0"/>
      <geometry>
        <mesh filename="left_sharpa_meshes/left_PP.STL"/>
      </geometry>
    </collision>
  </link>
  <joint name="left_middle_MCP_AA" type="revolute">
    <origin xyz="0 0 0" rpy="1.5708 0 0"/>
    <parent link="left_middle_MCP_VL"/>
    <child link="left_middle_PP"/>
    <axis xyz="0 0 1"/>
    <!-- <limit lower="-0.3491" upper="0.3491" effort="1.864" velocity="16.07692878" /> -->
    <limit lower="-0.03491" upper="0.03491" effort="1.864" velocity="16.07692878"/>
  </joint>
  <link name="left_middle_MP">
    <inertial>
      <origin xyz="0.015316 -0.00138561 6.27987E-08" rpy="0 0 0"/>
      <mass value="0.02509"/>
      <inertia ixx="1.00375E-06" ixy="-7.00446E-08" ixz="7.42125E-12" iyy="2.2637E-06" iyz="-2.26606E-12" izz="2.28516E-06"/>
    </inertial>
    <visual>
      <origin xyz="0 0 0" rpy="0 0 0"/>
      <geometry>
        <mesh filename="left_sharpa_meshes/left_MP_visual.STL"/>
      </geometry>
      <material name="">
        <color rgba="0.79216 0.81961 0.93333 1"/>
      </material>
    </visual>
    <collision>
      <origin xyz="0 0 0" rpy="0 0 0"/>
      <geometry>
        <mesh filename="left_sharpa_meshes/left_MP.STL"/>
      </geometry>
    </collision>
  </link>
  <joint name="left_middle_PIP" type="revolute">
    <origin xyz="0.047 0 0" rpy="-1.5708 0 0"/>
    <parent link="left_middle_PP"/>
    <child link="left_middle_MP"/>
    <axis xyz="0 0 1"/>
    <limit lower="0" upper="1.7453" effort="0.638" velocity="11.61831603"/>
  </joint>
  <link name="left_middle_DP">
    <inertial>
      <origin xyz="0.0127205 -0.00380991 -9.52663E-07" rpy="0 0 0"/>
      <mass value="0.003002"/>
      <inertia ixx="7.65598E-08" ixy="2.47622E-08" ixz="1.23922E-11" iyy="9.99792E-08" iyz="-4.16105E-12" izz="9.38245E-08"/>
    </inertial>
    <visual>
      <origin xyz="0 0 0" rpy="0 0 0"/>
      <geometry>
        <mesh filename="left_sharpa_meshes/left_DP_visual.STL"/>
      </geometry>
      <material name="">
        <color rgba="0.79216 0.81961 0.93333 1"/>
      </material>
    </visual>
    <collision>
      <origin xyz="0 0 0" rpy="0 0 0"/>
      <geometry>
        <mesh filename="left_sharpa_meshes/left_DP.STL"/>
      </geometry>
    </collision>
  </link>
  <joint name="left_middle_DIP" type="revolute">
    <origin xyz="0.0315 0 0" rpy="0 0 0"/>
    <parent link="left_middle_MP"/>
    <child link="left_middle_DP"/>
    <axis xyz="0 0 1"/>
    <limit lower="0" upper="1.3963" effort="0.189369" velocity="14.66594768"/>
  </joint>
  <link name="left_middle_elastomer">
    <inertial>
      <origin xyz="-4.34641E-07 -0.0183002 0.000412898" rpy="0 0 0"/>
      <mass value="0.00110"/>
      <inertia ixx="2.54635E-08" ixy="1.30327E-12" ixz="-2.13894E-13" iyy="2.14666E-08" iyz="5.39858E-09" izz="2.96037E-08"/>
    </inertial>
    <visual>
      <origin xyz="0 0 0" rpy="0 0 0"/>
      <geometry>
        <mesh filename="left_sharpa_meshes/elastomer_surface.STL"/>
      </geometry>
      <material name="">
        <color rgba="0.2 1 0.2 1"/>
      </material>
    </visual>
    <collision>
      <origin xyz="0 0 0" rpy="0 0 0"/>
      <geometry>
        <mesh filename="left_sharpa_meshes/elastomer.STL"/>
      </geometry>
    </collision>
  </link>
  <joint name="left_middle_elastomer_fix_joint" type="fixed">
    <origin xyz="0 0 0" rpy="1.5707963267949 -1.5707963267949 0"/>
    <parent link="left_middle_DP"/>
    <child link="left_middle_elastomer"/>
    <axis xyz="0 0 0"/>
  </joint>
  <link name="left_middle_fingertip">
    <inertial>
      <origin xyz="0.0 0.0 0.0" rpy="0 0 0"/>
      <mass value="1.0E-06"/>
      <inertia ixx="2.0E-12" ixy="0" ixz="0" iyy="2.0E-12" iyz="0" izz="2.0E-12"/>
    </inertial>
  </link>
  <joint name="left_middle_fingertip_fix_joint" type="fixed">
    <origin xyz="0 -0.0260092574262507 0" rpy="1.5707963267949 1.5707963267949 0"/>
    <parent link="left_middle_elastomer"/>
    <child link="left_middle_fingertip"/>
    <axis xyz="0 0 0"/>
  </joint>
  <link name="left_ring_MCP_VL">
    <inertial>
      <origin xyz="4.8E-09 0.00086981 3.6E-09" rpy="0 0 0"/>
      <mass value="1.0E-06"/>
      <inertia ixx="2.0E-12" ixy="0" ixz="0" iyy="2.0E-12" iyz="0" izz="2.0E-12"/>
    </inertial>
    <visual>
      <origin xyz="0 0 0" rpy="0 0 0"/>
      <geometry>
        <mesh filename="left_sharpa_meshes/left_MCP_VL_visual.STL"/>
      </geometry>
      <material name="">
        <color rgba="0.79216 0.81961 0.93333 1"/>
      </material>
    </visual>
    <collision>
      <origin xyz="0 0 0" rpy="0 0 0"/>
      <geometry>
        <mesh filename="left_sharpa_meshes/MCP_VL.STL"/>
      </geometry>
    </collision>
  </link>
  <joint name="left_4_ring_MCP_FE" type="revolute">
    <origin xyz="0.0015 0.0103 0.0927" rpy="0 -1.5708 -1.5708"/>
    <parent link="left_hand_C_MC"/>
    <child link="left_ring_MCP_VL"/>
    <axis xyz="0 0 1"/>
    <limit lower="-0.17453293" upper="1.5708" effort="1.864" velocity="16.07692878"/>
  </joint>
  <link name="left_ring_PP">
    <inertial>
      <origin xyz="0.0243772 -1.00263E-06 0.000755901" rpy="0 0 0"/>
      <mass value="0.04138"/>
      <inertia ixx="2.19643E-06" ixy="-5.66246E-11" ixz="-3.54371E-07" iyy="6.82371E-06" iyz="4.72597E-11" izz="6.51207E-06"/>
    </inertial>
    <visual>
      <origin xyz="0 0 0" rpy="0 0 0"/>
      <geometry>
        <mesh filename="left_sharpa_meshes/left_PP_visual.STL"/>
      </geometry>
      <material name="">
        <color rgba="0.79216 0.81961 0.93333 1"/>
      </material>
    </visual>
    <collision>
      <origin xyz="0 0 0" rpy="0 0 0"/>
      <geometry>
        <mesh filename="left_sharpa_meshes/left_PP.STL"/>
      </geometry>
    </collision>
  </link>
  <joint name="left_ring_MCP_AA" type="revolute">
    <origin xyz="0 0 0" rpy="1.5708 0 0"/>
    <parent link="left_ring_MCP_VL"/>
    <child link="left_ring_PP"/>
    <axis xyz="0 0 1"/>
    <!-- <limit lower="-0.3491" upper="0.3491" effort="1.864" velocity="16.07692878" /> -->
    <limit lower="-0.03491" upper="0.03491" effort="1.864" velocity="16.07692878"/>
  </joint>
  <link name="left_ring_MP">
    <inertial>
      <origin xyz="0.015316 -0.00138561 6.27987E-08" rpy="0 0 0"/>
      <mass value="0.02509"/>
      <inertia ixx="1.00375E-06" ixy="-7.00446E-08" ixz="7.42125E-12" iyy="2.2637E-06" iyz="-2.26606E-12" izz="2.28516E-06"/>
    </inertial>
    <visual>
      <origin xyz="0 0 0" rpy="0 0 0"/>
      <geometry>
        <mesh filename="left_sharpa_meshes/left_MP_visual.STL"/>
      </geometry>
      <material name="">
        <color rgba="0.79216 0.81961 0.93333 1"/>
      </material>
    </visual>
    <collision>
      <origin xyz="0 0 0" rpy="0 0 0"/>
      <geometry>
        <mesh filename="left_sharpa_meshes/left_MP.STL"/>
      </geometry>
    </collision>
  </link>
  <joint name="left_ring_PIP" type="revolute">
    <origin xyz="0.047 0 0" rpy="-1.5708 0 0"/>
    <parent link="left_ring_PP"/>
    <child link="left_ring_MP"/>
    <axis xyz="0 0 1"/>
    <limit lower="0" upper="1.7453" effort="0.638" velocity="11.61831603"/>
  </joint>
  <link name="left_ring_DP">
    <inertial>
      <origin xyz="0.0127205 -0.00380991 -9.52663E-07" rpy="0 0 0"/>
      <mass value="0.003002"/>
      <inertia ixx="7.65598E-08" ixy="2.47622E-08" ixz="1.23922E-11" iyy="9.99792E-08" iyz="-4.16105E-12" izz="9.38245E-08"/>
    </inertial>
    <visual>
      <origin xyz="0 0 0" rpy="0 0 0"/>
      <geometry>
        <mesh filename="left_sharpa_meshes/left_DP_visual.STL"/>
      </geometry>
      <material name="">
        <color rgba="0.79216 0.81961 0.93333 1"/>
      </material>
    </visual>
    <collision>
      <origin xyz="0 0 0" rpy="0 0 0"/>
      <geometry>
        <mesh filename="left_sharpa_meshes/left_DP.STL"/>
      </geometry>
    </collision>
  </link>
  <joint name="left_ring_DIP" type="revolute">
    <origin xyz="0.0315 0 0" rpy="0 0 0"/>
    <parent link="left_ring_MP"/>
    <child link="left_ring_DP"/>
    <axis xyz="0 0 1"/>
    <limit lower="0" upper="1.3963" effort="0.189369" velocity="14.66594768"/>
  </joint>
  <link name="left_ring_elastomer">
    <inertial>
      <origin xyz="-4.34641E-07 -0.0183002 0.000412898" rpy="0 0 0"/>
      <mass value="0.00110"/>
      <inertia ixx="2.54635E-08" ixy="1.30327E-12" ixz="-2.13894E-13" iyy="2.14666E-08" iyz="5.39858E-09" izz="2.96037E-08"/>
    </inertial>
    <visual>
      <origin xyz="0 0 0" rpy="0 0 0"/>
      <geometry>
        <mesh filename="left_sharpa_meshes/elastomer_surface.STL"/>
      </geometry>
      <material name="">
        <color rgba="0.2 1 0.2 1"/>
      </material>
    </visual>
    <collision>
      <origin xyz="0 0 0" rpy="0 0 0"/>
      <geometry>
        <mesh filename="left_sharpa_meshes/elastomer.STL"/>
      </geometry>
    </collision>
  </link>
  <joint name="left_ring_elastomer_fix_joint" type="fixed">
    <origin xyz="0 0 0" rpy="1.5708 -1.5708 0"/>
    <parent link="left_ring_DP"/>
    <child link="left_ring_elastomer"/>
    <axis xyz="0 0 0"/>
  </joint>
  <link name="left_ring_fingertip">
    <inertial>
      <origin xyz="0.0 0.0 0.0" rpy="0 0 0"/>
      <mass value="1.0E-06"/>
      <inertia ixx="2.0E-12" ixy="0" ixz="0" iyy="2.0E-12" iyz="0" izz="2.0E-12"/>
    </inertial>
  </link>
  <joint name="left_ring_fingertip_fix_joint" type="fixed">
    <origin xyz="0 -0.0260092574262507 0" rpy="1.5707963267949 1.5707963267949 0"/>
    <parent link="left_ring_elastomer"/>
    <child link="left_ring_fingertip"/>
    <axis xyz="0 0 0"/>
  </joint>
  <link name="left_pinky_MC">
    <inertial>
      <origin xyz="0.0107985 0.00598801 0.0335125" rpy="0 0 0"/>
      <mass value="0.12541"/>
      <inertia ixx="2.44379E-05" ixy="3.62784E-07" ixz="-8.00221E-07" iyy="3.57429E-05" iyz="4.68085E-07" izz="2.16786E-05"/>
    </inertial>
    <visual>
      <origin xyz="0 0 0" rpy="0 0 0"/>
      <geometry>
        <mesh filename="left_sharpa_meshes/left_pinky_MC_visual.STL"/>
      </geometry>
      <material name="">
        <color rgba="0.79216 0.81961 0.93333 1"/>
      </material>
    </visual>
    <collision>
      <origin xyz="0 0 0" rpy="0 0 0"/>
      <geometry>
        <mesh filename="left_sharpa_meshes/left_pinky_MC.STL"/>
      </geometry>
    </collision>
  </link>
  <joint name="left_5_pinky_CMC" type="revolute">
    <origin xyz="0.01136 0.0263 0.0867" rpy="-3.1416 0 3.1416"/>
    <parent link="left_hand_C_MC"/>
    <child link="left_pinky_MC"/>
    <axis xyz="0 0 1"/>
    <limit lower="0" upper="0.2618" effort="0.5285" velocity="35.07416159"/>
  </joint>
  <link name="left_pinky_MCP_VL">
    <inertial>
      <origin xyz="4.8E-09 0.00086981 -3.6E-09" rpy="0 0 0"/>
      <mass value="1.0E-06"/>
      <inertia ixx="2.0E-12" ixy="0" ixz="0" iyy="2.0E-12" iyz="0" izz="2.0E-12"/>
    </inertial>
    <visual>
      <origin xyz="0 0 0" rpy="0 0 0"/>
      <geometry>
        <mesh filename="left_sharpa_meshes/left_MCP_VL_visual.STL"/>
      </geometry>
      <material name="">
        <color rgba="0.79216 0.81961 0.93333 1"/>
      </material>
    </visual>
    <collision>
      <origin xyz="0 0 0" rpy="0 0 0"/>
      <geometry>
        <mesh filename="left_sharpa_meshes/MCP_VL.STL"/>
      </geometry>
    </collision>
  </link>
  <joint name="left_pinky_MCP_FE" type="revolute">
    <origin xyz="0.00836 0.0048 0" rpy="-1.5708 1.5708 0"/>
    <parent link="left_pinky_MC"/>
    <child link="left_pinky_MCP_VL"/>
    <axis xyz="0 0 1"/>
    <limit lower="-0.17453293" upper="1.5708" effort="1.864" velocity="16.07692878"/>
  </joint>
  <link name="left_pinky_PP">
    <inertial>
      <origin xyz="0.0243772 -1.00263E-06 0.000755901" rpy="0 0 0"/>
      <mass value="0.04138"/>
      <inertia ixx="2.19643E-06" ixy="-5.66246E-11" ixz="-3.54371E-07" iyy="6.82371E-06" iyz="4.72597E-11" izz="6.51207E-06"/>
    </inertial>
    <visual>
      <origin xyz="0 0 0" rpy="0 0 0"/>
      <geometry>
        <mesh filename="left_sharpa_meshes/left_PP_visual.STL"/>
      </geometry>
      <material name="">
        <color rgba="0.79216 0.81961 0.93333 1"/>
      </material>
    </visual>
    <collision>
      <origin xyz="0 0 0" rpy="0 0 0"/>
      <geometry>
        <mesh filename="left_sharpa_meshes/left_PP.STL"/>
      </geometry>
    </collision>
  </link>
  <joint name="left_pinky_MCP_AA" type="revolute">
    <origin xyz="0 0 0" rpy="1.5708 0 0"/>
    <parent link="left_pinky_MCP_VL"/>
    <child link="left_pinky_PP"/>
    <axis xyz="0 0 1"/>
    <!-- <limit lower="-0.3491" upper="0.3491" effort="1.864" velocity="16.07692878" /> -->
    <limit lower="-0.03491" upper="0.03491" effort="1.864" velocity="16.07692878"/>
  </joint>
  <link name="left_pinky_MP">
    <inertial>
      <origin xyz="0.015316 -0.00138561 6.27987E-08" rpy="0 0 0"/>
      <mass value="0.02509"/>
      <inertia ixx="1.00375E-06" ixy="-7.00446E-08" ixz="7.42125E-12" iyy="2.2637E-06" iyz="-2.26606E-12" izz="2.28516E-06"/>
    </inertial>
    <visual>
      <origin xyz="0 0 0" rpy="0 0 0"/>
      <geometry>
        <mesh filename="left_sharpa_meshes/left_MP_visual.STL"/>
      </geometry>
      <material name="">
        <color rgba="0.79216 0.81961 0.93333 1"/>
      </material>
    </visual>
    <collision>
      <origin xyz="0 0 0" rpy="0 0 0"/>
      <geometry>
        <mesh filename="left_sharpa_meshes/left_MP.STL"/>
      </geometry>
    </collision>
  </link>
  <joint name="left_pinky_PIP" type="revolute">
    <origin xyz="0.047 0 0" rpy="-1.5708 0 0"/>
    <parent link="left_pinky_PP"/>
    <child link="left_pinky_MP"/>
    <axis xyz="0 0 1"/>
    <limit lower="0" upper="1.7453" effort="0.638" velocity="11.61831603"/>
  </joint>
  <link name="left_pinky_DP">
    <inertial>
      <origin xyz="0.0127205 -0.00380991 -9.52663E-07" rpy="0 0 0"/>
      <mass value="0.003002"/>
      <inertia ixx="7.65598E-08" ixy="2.47622E-08" ixz="1.23922E-11" iyy="9.99792E-08" iyz="-4.16105E-12" izz="9.38245E-08"/>
    </inertial>
    <visual>
      <origin xyz="0 0 0" rpy="0 0 0"/>
      <geometry>
        <mesh filename="left_sharpa_meshes/left_DP_visual.STL"/>
      </geometry>
      <material name="">
        <color rgba="0.79216 0.81961 0.93333 1"/>
      </material>
    </visual>
    <collision>
      <origin xyz="0 0 0" rpy="0 0 0"/>
      <geometry>
        <mesh filename="left_sharpa_meshes/left_DP.STL"/>
      </geometry>
    </collision>
  </link>
  <joint name="left_pinky_DIP" type="revolute">
    <origin xyz="0.0315 0 0" rpy="0 0 0"/>
    <parent link="left_pinky_MP"/>
    <child link="left_pinky_DP"/>
    <axis xyz="0 0 1"/>
    <limit lower="0" upper="1.3963" effort="0.189369" velocity="14.66594768"/>
  </joint>
  <link name="left_pinky_elastomer">
    <inertial>
      <origin xyz="-4.34641E-07 -0.0183002 0.000412898" rpy="0 0 0"/>
      <mass value="0.00110"/>
      <inertia ixx="2.54635E-08" ixy="1.30327E-12" ixz="-2.13894E-13" iyy="2.14666E-08" iyz="5.39858E-09" izz="2.96037E-08"/>
    </inertial>
    <visual>
      <origin xyz="0 0 0" rpy="0 0 0"/>
      <geometry>
        <mesh filename="left_sharpa_meshes/elastomer_surface.STL"/>
      </geometry>
      <material name="">
        <color rgba="0.2 1 0.2 1"/>
      </material>
    </visual>
    <collision>
      <origin xyz="0 0 0" rpy="0 0 0"/>
      <geometry>
        <mesh filename="left_sharpa_meshes/elastomer.STL"/>
      </geometry>
    </collision>
  </link>
  <joint name="left_pinky_elastomer_fix_joint" type="fixed">
    <origin xyz="0 0 0" rpy="1.5707963267949 -1.5707963267949 0"/>
    <parent link="left_pinky_DP"/>
    <child link="left_pinky_elastomer"/>
    <axis xyz="0 0 0"/>
  </joint>
  <link name="left_pinky_fingertip">
    <inertial>
      <origin xyz="0.0 0.0 0.0" rpy="0 0 0"/>
      <mass value="1.0E-06"/>
      <inertia ixx="2.0E-12" ixy="0" ixz="0" iyy="2.0E-12" iyz="0" izz="2.0E-12"/>
    </inertial>
  </link>
  <joint name="left_pinky_fingertip_fix_joint" type="fixed">
    <origin xyz="0 -0.0260092574262507 0" rpy="1.5707963267949 1.5707963267949 0"/>
    <parent link="left_pinky_elastomer"/>
    <child link="left_pinky_fingertip"/>
    <axis xyz="0 0 0"/>
  </joint>
  <!-- ============================================================================= -->
  <!-- Create a different *root* for the hand -->
  <!-- Note: this offset is just eyeballed... -->
  <joint name="g1_sharpa" type="fixed">
    <parent link="left_wrist_yaw_link"/>
    <child link="sharpa_mount"/>
    <origin rpy="0 0 0" xyz="0 0 0"/>
  </joint>
</robot>